2017-01-16 21:35:06:pywws.Logger:pywws version 16.12.0, build 1367 (e917ba9)
2017-01-16 21:36:11:pywws.ToService(underground_rf):rsp: success
2017-01-16 21:36:11:pywws.Upload:[Errno -2] Name or service not known
2017-01-16 21:37:08:pywws.ToService(underground):rsp: success
2017-01-17 03:32:53:pywws.weather_station:setting sensor clock 5.14002
2017-01-17 03:32:53:pywws.weather_station:sensor clock drift 2.93665 2.62647
2017-01-17 19:32:00:pywws.weather_station:setting station clock 0.879192
2017-01-17 19:32:00:pywws.weather_station:station clock drift 0.00916042 0.00744866
2017-01-17 20:40:08:pywws.Logger:pywws version 16.12.0, build 1367 (e917ba9)
2017-01-17 20:41:08:pywws.ToService(underground_rf):rsp: success
2017-01-17 20:41:08:pywws.Upload:[Errno -2] Name or service not known
2017-01-17 20:42:08:pywws.ToService(underground):rsp: success
2017-01-22 20:05:06:pywws.Logger:pywws version 16.12.0, build 1367 (e917ba9)
2017-01-22 20:06:01:pywws.weather_station:setting sensor clock 25.993
2017-01-22 20:06:01:pywws.weather_station:sensor clock drift 3.66505 2.88611
2017-01-22 20:06:04:pywws.LiveLog:[Errno 2] No such file or directory
Traceback (most recent call last):
  File "/usr/local/lib/python2.7/dist-packages/pywws/LiveLog.py", line 88, in LiveLog
    tasks.do_live(data)
  File "/usr/local/lib/python2.7/dist-packages/pywws/Tasks.py", line 301, in do_live
    self._do_cron(calib_data)
  File "/usr/local/lib/python2.7/dist-packages/pywws/Tasks.py", line 294, in _do_cron
    self._do_common(sections, live_data)
  File "/usr/local/lib/python2.7/dist-packages/pywws/Tasks.py", line 246, in _do_common
    upload = self.do_plot(template)
  File "/usr/local/lib/python2.7/dist-packages/pywws/Tasks.py", line 402, in do_plot
    self.plotter.DoPlot(input_xml, output_file) == 0):
  File "/usr/local/lib/python2.7/dist-packages/pywws/Plot.py", line 739, in DoPlot
    subprocess.check_call(['gnuplot', cmd_file])
  File "/usr/lib/python2.7/subprocess.py", line 535, in check_call
    retcode = call(*popenargs, **kwargs)
  File "/usr/lib/python2.7/subprocess.py", line 522, in call
    return Popen(*popenargs, **kwargs).wait()
  File "/usr/lib/python2.7/subprocess.py", line 710, in __init__
    errread, errwrite)
  File "/usr/lib/python2.7/subprocess.py", line 1335, in _execute_child
    raise child_exception
OSError: [Errno 2] No such file or directory
2017-01-22 20:06:06:pywws.ToService(underground_rf):rsp: success
2017-01-22 20:10:07:pywws.Logger:pywws version 16.12.0, build 1367 (e917ba9)
2017-01-22 20:10:53:pywws.LiveLog:[Errno 2] No such file or directory
Traceback (most recent call last):
  File "/usr/local/lib/python2.7/dist-packages/pywws/LiveLog.py", line 88, in LiveLog
    tasks.do_live(data)
  File "/usr/local/lib/python2.7/dist-packages/pywws/Tasks.py", line 301, in do_live
    self._do_cron(calib_data)
  File "/usr/local/lib/python2.7/dist-packages/pywws/Tasks.py", line 294, in _do_cron
    self._do_common(sections, live_data)
  File "/usr/local/lib/python2.7/dist-packages/pywws/Tasks.py", line 246, in _do_common
    upload = self.do_plot(template)
  File "/usr/local/lib/python2.7/dist-packages/pywws/Tasks.py", line 402, in do_plot
    self.plotter.DoPlot(input_xml, output_file) == 0):
  File "/usr/local/lib/python2.7/dist-packages/pywws/Plot.py", line 739, in DoPlot
    subprocess.check_call(['gnuplot', cmd_file])
  File "/usr/lib/python2.7/subprocess.py", line 535, in check_call
    retcode = call(*popenargs, **kwargs)
  File "/usr/lib/python2.7/subprocess.py", line 522, in call
    return Popen(*popenargs, **kwargs).wait()
  File "/usr/lib/python2.7/subprocess.py", line 710, in __init__
    errread, errwrite)
  File "/usr/lib/python2.7/subprocess.py", line 1335, in _execute_child
    raise child_exception
OSError: [Errno 2] No such file or directory
2017-01-22 20:10:56:pywws.ToService(underground_rf):rsp: success
2017-01-22 20:15:06:pywws.Logger:pywws version 16.12.0, build 1367 (e917ba9)
2017-01-22 20:15:41:pywws.LiveLog:[Errno 2] No such file or directory
Traceback (most recent call last):
  File "/usr/local/lib/python2.7/dist-packages/pywws/LiveLog.py", line 88, in LiveLog
    tasks.do_live(data)
  File "/usr/local/lib/python2.7/dist-packages/pywws/Tasks.py", line 301, in do_live
    self._do_cron(calib_data)
  File "/usr/local/lib/python2.7/dist-packages/pywws/Tasks.py", line 294, in _do_cron
    self._do_common(sections, live_data)
  File "/usr/local/lib/python2.7/dist-packages/pywws/Tasks.py", line 246, in _do_common
    upload = self.do_plot(template)
  File "/usr/local/lib/python2.7/dist-packages/pywws/Tasks.py", line 402, in do_plot
    self.plotter.DoPlot(input_xml, output_file) == 0):
  File "/usr/local/lib/python2.7/dist-packages/pywws/Plot.py", line 739, in DoPlot
    subprocess.check_call(['gnuplot', cmd_file])
  File "/usr/lib/python2.7/subprocess.py", line 535, in check_call
    retcode = call(*popenargs, **kwargs)
  File "/usr/lib/python2.7/subprocess.py", line 522, in call
    return Popen(*popenargs, **kwargs).wait()
  File "/usr/lib/python2.7/subprocess.py", line 710, in __init__
    errread, errwrite)
  File "/usr/lib/python2.7/subprocess.py", line 1335, in _execute_child
    raise child_exception
OSError: [Errno 2] No such file or directory
2017-01-22 20:15:44:pywws.ToService(underground_rf):rsp: success
2017-01-22 20:20:07:pywws.Logger:pywws version 16.12.0, build 1367 (e917ba9)
2017-01-22 20:20:30:pywws.LiveLog:[Errno 2] No such file or directory
Traceback (most recent call last):
  File "/usr/local/lib/python2.7/dist-packages/pywws/LiveLog.py", line 88, in LiveLog
    tasks.do_live(data)
  File "/usr/local/lib/python2.7/dist-packages/pywws/Tasks.py", line 301, in do_live
    self._do_cron(calib_data)
  File "/usr/local/lib/python2.7/dist-packages/pywws/Tasks.py", line 294, in _do_cron
    self._do_common(sections, live_data)
  File "/usr/local/lib/python2.7/dist-packages/pywws/Tasks.py", line 246, in _do_common
    upload = self.do_plot(template)
  File "/usr/local/lib/python2.7/dist-packages/pywws/Tasks.py", line 402, in do_plot
    self.plotter.DoPlot(input_xml, output_file) == 0):
  File "/usr/local/lib/python2.7/dist-packages/pywws/Plot.py", line 739, in DoPlot
    subprocess.check_call(['gnuplot', cmd_file])
  File "/usr/lib/python2.7/subprocess.py", line 535, in check_call
    retcode = call(*popenargs, **kwargs)
  File "/usr/lib/python2.7/subprocess.py", line 522, in call
    return Popen(*popenargs, **kwargs).wait()
  File "/usr/lib/python2.7/subprocess.py", line 710, in __init__
    errread, errwrite)
  File "/usr/lib/python2.7/subprocess.py", line 1335, in _execute_child
    raise child_exception
OSError: [Errno 2] No such file or directory
2017-01-22 20:20:33:pywws.ToService(underground_rf):rsp: success
2017-01-22 20:25:06:pywws.Logger:pywws version 16.12.0, build 1367 (e917ba9)
2017-01-22 20:26:06:pywws.LiveLog:[Errno 2] No such file or directory
Traceback (most recent call last):
  File "/usr/local/lib/python2.7/dist-packages/pywws/LiveLog.py", line 88, in LiveLog
    tasks.do_live(data)
  File "/usr/local/lib/python2.7/dist-packages/pywws/Tasks.py", line 301, in do_live
    self._do_cron(calib_data)
  File "/usr/local/lib/python2.7/dist-packages/pywws/Tasks.py", line 294, in _do_cron
    self._do_common(sections, live_data)
  File "/usr/local/lib/python2.7/dist-packages/pywws/Tasks.py", line 246, in _do_common
    upload = self.do_plot(template)
  File "/usr/local/lib/python2.7/dist-packages/pywws/Tasks.py", line 402, in do_plot
    self.plotter.DoPlot(input_xml, output_file) == 0):
  File "/usr/local/lib/python2.7/dist-packages/pywws/Plot.py", line 739, in DoPlot
    subprocess.check_call(['gnuplot', cmd_file])
  File "/usr/lib/python2.7/subprocess.py", line 535, in check_call
    retcode = call(*popenargs, **kwargs)
  File "/usr/lib/python2.7/subprocess.py", line 522, in call
    return Popen(*popenargs, **kwargs).wait()
  File "/usr/lib/python2.7/subprocess.py", line 710, in __init__
    errread, errwrite)
  File "/usr/lib/python2.7/subprocess.py", line 1335, in _execute_child
    raise child_exception
OSError: [Errno 2] No such file or directory
2017-01-22 20:26:08:pywws.ToService(underground_rf):rsp: success
2017-01-22 20:30:07:pywws.Logger:pywws version 16.12.0, build 1367 (e917ba9)
2017-01-22 20:30:53:pywws.LiveLog:[Errno 2] No such file or directory
Traceback (most recent call last):
  File "/usr/local/lib/python2.7/dist-packages/pywws/LiveLog.py", line 88, in LiveLog
    tasks.do_live(data)
  File "/usr/local/lib/python2.7/dist-packages/pywws/Tasks.py", line 301, in do_live
    self._do_cron(calib_data)
  File "/usr/local/lib/python2.7/dist-packages/pywws/Tasks.py", line 294, in _do_cron
    self._do_common(sections, live_data)
  File "/usr/local/lib/python2.7/dist-packages/pywws/Tasks.py", line 246, in _do_common
    upload = self.do_plot(template)
  File "/usr/local/lib/python2.7/dist-packages/pywws/Tasks.py", line 402, in do_plot
    self.plotter.DoPlot(input_xml, output_file) == 0):
  File "/usr/local/lib/python2.7/dist-packages/pywws/Plot.py", line 739, in DoPlot
    subprocess.check_call(['gnuplot', cmd_file])
  File "/usr/lib/python2.7/subprocess.py", line 535, in check_call
    retcode = call(*popenargs, **kwargs)
  File "/usr/lib/python2.7/subprocess.py", line 522, in call
    return Popen(*popenargs, **kwargs).wait()
  File "/usr/lib/python2.7/subprocess.py", line 710, in __init__
    errread, errwrite)
  File "/usr/lib/python2.7/subprocess.py", line 1335, in _execute_child
    raise child_exception
OSError: [Errno 2] No such file or directory
2017-01-22 20:30:56:pywws.ToService(underground_rf):rsp: success
2017-01-22 20:35:06:pywws.Logger:pywws version 16.12.0, build 1367 (e917ba9)
2017-01-22 20:35:42:pywws.LiveLog:[Errno 2] No such file or directory
Traceback (most recent call last):
  File "/usr/local/lib/python2.7/dist-packages/pywws/LiveLog.py", line 88, in LiveLog
    tasks.do_live(data)
  File "/usr/local/lib/python2.7/dist-packages/pywws/Tasks.py", line 301, in do_live
    self._do_cron(calib_data)
  File "/usr/local/lib/python2.7/dist-packages/pywws/Tasks.py", line 294, in _do_cron
    self._do_common(sections, live_data)
  File "/usr/local/lib/python2.7/dist-packages/pywws/Tasks.py", line 246, in _do_common
    upload = self.do_plot(template)
  File "/usr/local/lib/python2.7/dist-packages/pywws/Tasks.py", line 402, in do_plot
    self.plotter.DoPlot(input_xml, output_file) == 0):
  File "/usr/local/lib/python2.7/dist-packages/pywws/Plot.py", line 739, in DoPlot
    subprocess.check_call(['gnuplot', cmd_file])
  File "/usr/lib/python2.7/subprocess.py", line 535, in check_call
    retcode = call(*popenargs, **kwargs)
  File "/usr/lib/python2.7/subprocess.py", line 522, in call
    return Popen(*popenargs, **kwargs).wait()
  File "/usr/lib/python2.7/subprocess.py", line 710, in __init__
    errread, errwrite)
  File "/usr/lib/python2.7/subprocess.py", line 1335, in _execute_child
    raise child_exception
OSError: [Errno 2] No such file or directory
2017-01-22 20:35:44:pywws.ToService(underground_rf):rsp: success
2017-01-22 20:40:07:pywws.Logger:pywws version 16.12.0, build 1367 (e917ba9)
2017-01-22 20:40:30:pywws.LiveLog:[Errno 2] No such file or directory
Traceback (most recent call last):
  File "/usr/local/lib/python2.7/dist-packages/pywws/LiveLog.py", line 88, in LiveLog
    tasks.do_live(data)
  File "/usr/local/lib/python2.7/dist-packages/pywws/Tasks.py", line 301, in do_live
    self._do_cron(calib_data)
  File "/usr/local/lib/python2.7/dist-packages/pywws/Tasks.py", line 294, in _do_cron
    self._do_common(sections, live_data)
  File "/usr/local/lib/python2.7/dist-packages/pywws/Tasks.py", line 246, in _do_common
    upload = self.do_plot(template)
  File "/usr/local/lib/python2.7/dist-packages/pywws/Tasks.py", line 402, in do_plot
    self.plotter.DoPlot(input_xml, output_file) == 0):
  File "/usr/local/lib/python2.7/dist-packages/pywws/Plot.py", line 739, in DoPlot
    subprocess.check_call(['gnuplot', cmd_file])
  File "/usr/lib/python2.7/subprocess.py", line 535, in check_call
    retcode = call(*popenargs, **kwargs)
  File "/usr/lib/python2.7/subprocess.py", line 522, in call
    return Popen(*popenargs, **kwargs).wait()
  File "/usr/lib/python2.7/subprocess.py", line 710, in __init__
    errread, errwrite)
  File "/usr/lib/python2.7/subprocess.py", line 1335, in _execute_child
    raise child_exception
OSError: [Errno 2] No such file or directory
2017-01-22 20:40:32:pywws.ToService(underground_rf):rsp: success
2017-01-22 20:45:06:pywws.Logger:pywws version 16.12.0, build 1367 (e917ba9)
2017-01-22 20:46:06:pywws.LiveLog:[Errno 2] No such file or directory
Traceback (most recent call last):
  File "/usr/local/lib/python2.7/dist-packages/pywws/LiveLog.py", line 88, in LiveLog
    tasks.do_live(data)
  File "/usr/local/lib/python2.7/dist-packages/pywws/Tasks.py", line 301, in do_live
    self._do_cron(calib_data)
  File "/usr/local/lib/python2.7/dist-packages/pywws/Tasks.py", line 294, in _do_cron
    self._do_common(sections, live_data)
  File "/usr/local/lib/python2.7/dist-packages/pywws/Tasks.py", line 246, in _do_common
    upload = self.do_plot(template)
  File "/usr/local/lib/python2.7/dist-packages/pywws/Tasks.py", line 402, in do_plot
    self.plotter.DoPlot(input_xml, output_file) == 0):
  File "/usr/local/lib/python2.7/dist-packages/pywws/Plot.py", line 739, in DoPlot
    subprocess.check_call(['gnuplot', cmd_file])
  File "/usr/lib/python2.7/subprocess.py", line 535, in check_call
    retcode = call(*popenargs, **kwargs)
  File "/usr/lib/python2.7/subprocess.py", line 522, in call
    return Popen(*popenargs, **kwargs).wait()
  File "/usr/lib/python2.7/subprocess.py", line 710, in __init__
    errread, errwrite)
  File "/usr/lib/python2.7/subprocess.py", line 1335, in _execute_child
    raise child_exception
OSError: [Errno 2] No such file or directory
2017-01-22 20:46:08:pywws.ToService(underground_rf):rsp: success
2017-01-22 20:50:07:pywws.Logger:pywws version 16.12.0, build 1367 (e917ba9)
2017-01-22 20:50:54:pywws.LiveLog:[Errno 2] No such file or directory
Traceback (most recent call last):
  File "/usr/local/lib/python2.7/dist-packages/pywws/LiveLog.py", line 88, in LiveLog
    tasks.do_live(data)
  File "/usr/local/lib/python2.7/dist-packages/pywws/Tasks.py", line 301, in do_live
    self._do_cron(calib_data)
  File "/usr/local/lib/python2.7/dist-packages/pywws/Tasks.py", line 294, in _do_cron
    self._do_common(sections, live_data)
  File "/usr/local/lib/python2.7/dist-packages/pywws/Tasks.py", line 246, in _do_common
    upload = self.do_plot(template)
  File "/usr/local/lib/python2.7/dist-packages/pywws/Tasks.py", line 402, in do_plot
    self.plotter.DoPlot(input_xml, output_file) == 0):
  File "/usr/local/lib/python2.7/dist-packages/pywws/Plot.py", line 739, in DoPlot
    subprocess.check_call(['gnuplot', cmd_file])
  File "/usr/lib/python2.7/subprocess.py", line 535, in check_call
    retcode = call(*popenargs, **kwargs)
  File "/usr/lib/python2.7/subprocess.py", line 522, in call
    return Popen(*popenargs, **kwargs).wait()
  File "/usr/lib/python2.7/subprocess.py", line 710, in __init__
    errread, errwrite)
  File "/usr/lib/python2.7/subprocess.py", line 1335, in _execute_child
    raise child_exception
OSError: [Errno 2] No such file or directory
2017-01-22 20:50:56:pywws.ToService(underground_rf):rsp: success
2017-01-22 20:55:07:pywws.Logger:pywws version 16.12.0, build 1367 (e917ba9)
2017-01-22 20:55:42:pywws.LiveLog:[Errno 2] No such file or directory
Traceback (most recent call last):
  File "/usr/local/lib/python2.7/dist-packages/pywws/LiveLog.py", line 88, in LiveLog
    tasks.do_live(data)
  File "/usr/local/lib/python2.7/dist-packages/pywws/Tasks.py", line 301, in do_live
    self._do_cron(calib_data)
  File "/usr/local/lib/python2.7/dist-packages/pywws/Tasks.py", line 294, in _do_cron
    self._do_common(sections, live_data)
  File "/usr/local/lib/python2.7/dist-packages/pywws/Tasks.py", line 246, in _do_common
    upload = self.do_plot(template)
  File "/usr/local/lib/python2.7/dist-packages/pywws/Tasks.py", line 402, in do_plot
    self.plotter.DoPlot(input_xml, output_file) == 0):
  File "/usr/local/lib/python2.7/dist-packages/pywws/Plot.py", line 739, in DoPlot
    subprocess.check_call(['gnuplot', cmd_file])
  File "/usr/lib/python2.7/subprocess.py", line 535, in check_call
    retcode = call(*popenargs, **kwargs)
  File "/usr/lib/python2.7/subprocess.py", line 522, in call
    return Popen(*popenargs, **kwargs).wait()
  File "/usr/lib/python2.7/subprocess.py", line 710, in __init__
    errread, errwrite)
  File "/usr/lib/python2.7/subprocess.py", line 1335, in _execute_child
    raise child_exception
OSError: [Errno 2] No such file or directory
2017-01-22 20:55:44:pywws.ToService(underground_rf):rsp: success
2017-01-22 21:00:07:pywws.Logger:pywws version 16.12.0, build 1367 (e917ba9)
2017-01-22 21:00:30:pywws.LiveLog:[Errno 2] No such file or directory
Traceback (most recent call last):
  File "/usr/local/lib/python2.7/dist-packages/pywws/LiveLog.py", line 88, in LiveLog
    tasks.do_live(data)
  File "/usr/local/lib/python2.7/dist-packages/pywws/Tasks.py", line 301, in do_live
    self._do_cron(calib_data)
  File "/usr/local/lib/python2.7/dist-packages/pywws/Tasks.py", line 294, in _do_cron
    self._do_common(sections, live_data)
  File "/usr/local/lib/python2.7/dist-packages/pywws/Tasks.py", line 246, in _do_common
    upload = self.do_plot(template)
  File "/usr/local/lib/python2.7/dist-packages/pywws/Tasks.py", line 402, in do_plot
    self.plotter.DoPlot(input_xml, output_file) == 0):
  File "/usr/local/lib/python2.7/dist-packages/pywws/Plot.py", line 739, in DoPlot
    subprocess.check_call(['gnuplot', cmd_file])
  File "/usr/lib/python2.7/subprocess.py", line 535, in check_call
    retcode = call(*popenargs, **kwargs)
  File "/usr/lib/python2.7/subprocess.py", line 522, in call
    return Popen(*popenargs, **kwargs).wait()
  File "/usr/lib/python2.7/subprocess.py", line 710, in __init__
    errread, errwrite)
  File "/usr/lib/python2.7/subprocess.py", line 1335, in _execute_child
    raise child_exception
OSError: [Errno 2] No such file or directory
2017-01-22 21:00:33:pywws.ToService(underground_rf):rsp: success
2017-01-22 21:05:06:pywws.Logger:pywws version 16.12.0, build 1367 (e917ba9)
2017-01-22 21:06:06:pywws.LiveLog:[Errno 2] No such file or directory
Traceback (most recent call last):
  File "/usr/local/lib/python2.7/dist-packages/pywws/LiveLog.py", line 88, in LiveLog
    tasks.do_live(data)
  File "/usr/local/lib/python2.7/dist-packages/pywws/Tasks.py", line 301, in do_live
    self._do_cron(calib_data)
  File "/usr/local/lib/python2.7/dist-packages/pywws/Tasks.py", line 294, in _do_cron
    self._do_common(sections, live_data)
  File "/usr/local/lib/python2.7/dist-packages/pywws/Tasks.py", line 246, in _do_common
    upload = self.do_plot(template)
  File "/usr/local/lib/python2.7/dist-packages/pywws/Tasks.py", line 402, in do_plot
    self.plotter.DoPlot(input_xml, output_file) == 0):
  File "/usr/local/lib/python2.7/dist-packages/pywws/Plot.py", line 739, in DoPlot
    subprocess.check_call(['gnuplot', cmd_file])
  File "/usr/lib/python2.7/subprocess.py", line 535, in check_call
    retcode = call(*popenargs, **kwargs)
  File "/usr/lib/python2.7/subprocess.py", line 522, in call
    return Popen(*popenargs, **kwargs).wait()
  File "/usr/lib/python2.7/subprocess.py", line 710, in __init__
    errread, errwrite)
  File "/usr/lib/python2.7/subprocess.py", line 1335, in _execute_child
    raise child_exception
OSError: [Errno 2] No such file or directory
2017-01-22 21:06:08:pywws.ToService(underground_rf):rsp: success
2017-01-22 21:10:07:pywws.Logger:pywws version 16.12.0, build 1367 (e917ba9)
2017-01-22 21:10:54:pywws.LiveLog:[Errno 2] No such file or directory
Traceback (most recent call last):
  File "/usr/local/lib/python2.7/dist-packages/pywws/LiveLog.py", line 88, in LiveLog
    tasks.do_live(data)
  File "/usr/local/lib/python2.7/dist-packages/pywws/Tasks.py", line 301, in do_live
    self._do_cron(calib_data)
  File "/usr/local/lib/python2.7/dist-packages/pywws/Tasks.py", line 294, in _do_cron
    self._do_common(sections, live_data)
  File "/usr/local/lib/python2.7/dist-packages/pywws/Tasks.py", line 246, in _do_common
    upload = self.do_plot(template)
  File "/usr/local/lib/python2.7/dist-packages/pywws/Tasks.py", line 402, in do_plot
    self.plotter.DoPlot(input_xml, output_file) == 0):
  File "/usr/local/lib/python2.7/dist-packages/pywws/Plot.py", line 739, in DoPlot
    subprocess.check_call(['gnuplot', cmd_file])
  File "/usr/lib/python2.7/subprocess.py", line 535, in check_call
    retcode = call(*popenargs, **kwargs)
  File "/usr/lib/python2.7/subprocess.py", line 522, in call
    return Popen(*popenargs, **kwargs).wait()
  File "/usr/lib/python2.7/subprocess.py", line 710, in __init__
    errread, errwrite)
  File "/usr/lib/python2.7/subprocess.py", line 1335, in _execute_child
    raise child_exception
OSError: [Errno 2] No such file or directory
2017-01-22 21:10:56:pywws.ToService(underground_rf):rsp: success
2017-01-22 21:15:06:pywws.Logger:pywws version 16.12.0, build 1367 (e917ba9)
2017-01-22 21:15:42:pywws.LiveLog:[Errno 2] No such file or directory
Traceback (most recent call last):
  File "/usr/local/lib/python2.7/dist-packages/pywws/LiveLog.py", line 88, in LiveLog
    tasks.do_live(data)
  File "/usr/local/lib/python2.7/dist-packages/pywws/Tasks.py", line 301, in do_live
    self._do_cron(calib_data)
  File "/usr/local/lib/python2.7/dist-packages/pywws/Tasks.py", line 294, in _do_cron
    self._do_common(sections, live_data)
  File "/usr/local/lib/python2.7/dist-packages/pywws/Tasks.py", line 246, in _do_common
    upload = self.do_plot(template)
  File "/usr/local/lib/python2.7/dist-packages/pywws/Tasks.py", line 402, in do_plot
    self.plotter.DoPlot(input_xml, output_file) == 0):
  File "/usr/local/lib/python2.7/dist-packages/pywws/Plot.py", line 739, in DoPlot
    subprocess.check_call(['gnuplot', cmd_file])
  File "/usr/lib/python2.7/subprocess.py", line 535, in check_call
    retcode = call(*popenargs, **kwargs)
  File "/usr/lib/python2.7/subprocess.py", line 522, in call
    return Popen(*popenargs, **kwargs).wait()
  File "/usr/lib/python2.7/subprocess.py", line 710, in __init__
    errread, errwrite)
  File "/usr/lib/python2.7/subprocess.py", line 1335, in _execute_child
    raise child_exception
OSError: [Errno 2] No such file or directory
2017-01-22 21:15:44:pywws.ToService(underground_rf):rsp: success
2017-01-22 21:20:07:pywws.Logger:pywws version 16.12.0, build 1367 (e917ba9)
2017-01-22 21:20:30:pywws.LiveLog:[Errno 2] No such file or directory
Traceback (most recent call last):
  File "/usr/local/lib/python2.7/dist-packages/pywws/LiveLog.py", line 88, in LiveLog
    tasks.do_live(data)
  File "/usr/local/lib/python2.7/dist-packages/pywws/Tasks.py", line 301, in do_live
    self._do_cron(calib_data)
  File "/usr/local/lib/python2.7/dist-packages/pywws/Tasks.py", line 294, in _do_cron
    self._do_common(sections, live_data)
  File "/usr/local/lib/python2.7/dist-packages/pywws/Tasks.py", line 246, in _do_common
    upload = self.do_plot(template)
  File "/usr/local/lib/python2.7/dist-packages/pywws/Tasks.py", line 402, in do_plot
    self.plotter.DoPlot(input_xml, output_file) == 0):
  File "/usr/local/lib/python2.7/dist-packages/pywws/Plot.py", line 739, in DoPlot
    subprocess.check_call(['gnuplot', cmd_file])
  File "/usr/lib/python2.7/subprocess.py", line 535, in check_call
    retcode = call(*popenargs, **kwargs)
  File "/usr/lib/python2.7/subprocess.py", line 522, in call
    return Popen(*popenargs, **kwargs).wait()
  File "/usr/lib/python2.7/subprocess.py", line 710, in __init__
    errread, errwrite)
  File "/usr/lib/python2.7/subprocess.py", line 1335, in _execute_child
    raise child_exception
OSError: [Errno 2] No such file or directory
2017-01-22 21:20:32:pywws.ToService(underground_rf):rsp: success
2017-01-22 21:25:06:pywws.Logger:pywws version 16.12.0, build 1367 (e917ba9)
2017-01-22 21:26:06:pywws.LiveLog:[Errno 2] No such file or directory
Traceback (most recent call last):
  File "/usr/local/lib/python2.7/dist-packages/pywws/LiveLog.py", line 88, in LiveLog
    tasks.do_live(data)
  File "/usr/local/lib/python2.7/dist-packages/pywws/Tasks.py", line 301, in do_live
    self._do_cron(calib_data)
  File "/usr/local/lib/python2.7/dist-packages/pywws/Tasks.py", line 294, in _do_cron
    self._do_common(sections, live_data)
  File "/usr/local/lib/python2.7/dist-packages/pywws/Tasks.py", line 246, in _do_common
    upload = self.do_plot(template)
  File "/usr/local/lib/python2.7/dist-packages/pywws/Tasks.py", line 402, in do_plot
    self.plotter.DoPlot(input_xml, output_file) == 0):
  File "/usr/local/lib/python2.7/dist-packages/pywws/Plot.py", line 739, in DoPlot
    subprocess.check_call(['gnuplot', cmd_file])
  File "/usr/lib/python2.7/subprocess.py", line 535, in check_call
    retcode = call(*popenargs, **kwargs)
  File "/usr/lib/python2.7/subprocess.py", line 522, in call
    return Popen(*popenargs, **kwargs).wait()
  File "/usr/lib/python2.7/subprocess.py", line 710, in __init__
    errread, errwrite)
  File "/usr/lib/python2.7/subprocess.py", line 1335, in _execute_child
    raise child_exception
OSError: [Errno 2] No such file or directory
2017-01-22 21:26:08:pywws.ToService(underground_rf):rsp: success
2017-01-22 21:30:07:pywws.Logger:pywws version 16.12.0, build 1367 (e917ba9)
2017-01-22 21:30:54:pywws.LiveLog:[Errno 2] No such file or directory
Traceback (most recent call last):
  File "/usr/local/lib/python2.7/dist-packages/pywws/LiveLog.py", line 88, in LiveLog
    tasks.do_live(data)
  File "/usr/local/lib/python2.7/dist-packages/pywws/Tasks.py", line 301, in do_live
    self._do_cron(calib_data)
  File "/usr/local/lib/python2.7/dist-packages/pywws/Tasks.py", line 294, in _do_cron
    self._do_common(sections, live_data)
  File "/usr/local/lib/python2.7/dist-packages/pywws/Tasks.py", line 246, in _do_common
    upload = self.do_plot(template)
  File "/usr/local/lib/python2.7/dist-packages/pywws/Tasks.py", line 402, in do_plot
    self.plotter.DoPlot(input_xml, output_file) == 0):
  File "/usr/local/lib/python2.7/dist-packages/pywws/Plot.py", line 739, in DoPlot
    subprocess.check_call(['gnuplot', cmd_file])
  File "/usr/lib/python2.7/subprocess.py", line 535, in check_call
    retcode = call(*popenargs, **kwargs)
  File "/usr/lib/python2.7/subprocess.py", line 522, in call
    return Popen(*popenargs, **kwargs).wait()
  File "/usr/lib/python2.7/subprocess.py", line 710, in __init__
    errread, errwrite)
  File "/usr/lib/python2.7/subprocess.py", line 1335, in _execute_child
    raise child_exception
OSError: [Errno 2] No such file or directory
2017-01-22 21:30:56:pywws.ToService(underground_rf):rsp: success
2017-01-22 21:35:06:pywws.Logger:pywws version 16.12.0, build 1367 (e917ba9)
2017-01-22 21:35:42:pywws.LiveLog:[Errno 2] No such file or directory
Traceback (most recent call last):
  File "/usr/local/lib/python2.7/dist-packages/pywws/LiveLog.py", line 88, in LiveLog
    tasks.do_live(data)
  File "/usr/local/lib/python2.7/dist-packages/pywws/Tasks.py", line 301, in do_live
    self._do_cron(calib_data)
  File "/usr/local/lib/python2.7/dist-packages/pywws/Tasks.py", line 294, in _do_cron
    self._do_common(sections, live_data)
  File "/usr/local/lib/python2.7/dist-packages/pywws/Tasks.py", line 246, in _do_common
    upload = self.do_plot(template)
  File "/usr/local/lib/python2.7/dist-packages/pywws/Tasks.py", line 402, in do_plot
    self.plotter.DoPlot(input_xml, output_file) == 0):
  File "/usr/local/lib/python2.7/dist-packages/pywws/Plot.py", line 739, in DoPlot
    subprocess.check_call(['gnuplot', cmd_file])
  File "/usr/lib/python2.7/subprocess.py", line 535, in check_call
    retcode = call(*popenargs, **kwargs)
  File "/usr/lib/python2.7/subprocess.py", line 522, in call
    return Popen(*popenargs, **kwargs).wait()
  File "/usr/lib/python2.7/subprocess.py", line 710, in __init__
    errread, errwrite)
  File "/usr/lib/python2.7/subprocess.py", line 1335, in _execute_child
    raise child_exception
OSError: [Errno 2] No such file or directory
2017-01-22 21:35:44:pywws.ToService(underground_rf):rsp: success
2017-01-22 21:40:07:pywws.Logger:pywws version 16.12.0, build 1367 (e917ba9)
2017-01-22 21:40:30:pywws.LiveLog:[Errno 2] No such file or directory
Traceback (most recent call last):
  File "/usr/local/lib/python2.7/dist-packages/pywws/LiveLog.py", line 88, in LiveLog
    tasks.do_live(data)
  File "/usr/local/lib/python2.7/dist-packages/pywws/Tasks.py", line 301, in do_live
    self._do_cron(calib_data)
  File "/usr/local/lib/python2.7/dist-packages/pywws/Tasks.py", line 294, in _do_cron
    self._do_common(sections, live_data)
  File "/usr/local/lib/python2.7/dist-packages/pywws/Tasks.py", line 246, in _do_common
    upload = self.do_plot(template)
  File "/usr/local/lib/python2.7/dist-packages/pywws/Tasks.py", line 402, in do_plot
    self.plotter.DoPlot(input_xml, output_file) == 0):
  File "/usr/local/lib/python2.7/dist-packages/pywws/Plot.py", line 739, in DoPlot
    subprocess.check_call(['gnuplot', cmd_file])
  File "/usr/lib/python2.7/subprocess.py", line 535, in check_call
    retcode = call(*popenargs, **kwargs)
  File "/usr/lib/python2.7/subprocess.py", line 522, in call
    return Popen(*popenargs, **kwargs).wait()
  File "/usr/lib/python2.7/subprocess.py", line 710, in __init__
    errread, errwrite)
  File "/usr/lib/python2.7/subprocess.py", line 1335, in _execute_child
    raise child_exception
OSError: [Errno 2] No such file or directory
2017-01-22 21:40:32:pywws.ToService(underground_rf):rsp: success
2017-01-22 21:45:06:pywws.Logger:pywws version 16.12.0, build 1367 (e917ba9)
2017-01-22 21:46:07:pywws.LiveLog:[Errno 2] No such file or directory
Traceback (most recent call last):
  File "/usr/local/lib/python2.7/dist-packages/pywws/LiveLog.py", line 88, in LiveLog
    tasks.do_live(data)
  File "/usr/local/lib/python2.7/dist-packages/pywws/Tasks.py", line 301, in do_live
    self._do_cron(calib_data)
  File "/usr/local/lib/python2.7/dist-packages/pywws/Tasks.py", line 294, in _do_cron
    self._do_common(sections, live_data)
  File "/usr/local/lib/python2.7/dist-packages/pywws/Tasks.py", line 246, in _do_common
    upload = self.do_plot(template)
  File "/usr/local/lib/python2.7/dist-packages/pywws/Tasks.py", line 402, in do_plot
    self.plotter.DoPlot(input_xml, output_file) == 0):
  File "/usr/local/lib/python2.7/dist-packages/pywws/Plot.py", line 739, in DoPlot
    subprocess.check_call(['gnuplot', cmd_file])
  File "/usr/lib/python2.7/subprocess.py", line 535, in check_call
    retcode = call(*popenargs, **kwargs)
  File "/usr/lib/python2.7/subprocess.py", line 522, in call
    return Popen(*popenargs, **kwargs).wait()
  File "/usr/lib/python2.7/subprocess.py", line 710, in __init__
    errread, errwrite)
  File "/usr/lib/python2.7/subprocess.py", line 1335, in _execute_child
    raise child_exception
OSError: [Errno 2] No such file or directory
2017-01-22 21:46:09:pywws.ToService(underground_rf):rsp: success
2017-01-22 21:50:06:pywws.Logger:pywws version 16.12.0, build 1367 (e917ba9)
2017-01-22 21:50:55:pywws.LiveLog:[Errno 2] No such file or directory
Traceback (most recent call last):
  File "/usr/local/lib/python2.7/dist-packages/pywws/LiveLog.py", line 88, in LiveLog
    tasks.do_live(data)
  File "/usr/local/lib/python2.7/dist-packages/pywws/Tasks.py", line 301, in do_live
    self._do_cron(calib_data)
  File "/usr/local/lib/python2.7/dist-packages/pywws/Tasks.py", line 294, in _do_cron
    self._do_common(sections, live_data)
  File "/usr/local/lib/python2.7/dist-packages/pywws/Tasks.py", line 246, in _do_common
    upload = self.do_plot(template)
  File "/usr/local/lib/python2.7/dist-packages/pywws/Tasks.py", line 402, in do_plot
    self.plotter.DoPlot(input_xml, output_file) == 0):
  File "/usr/local/lib/python2.7/dist-packages/pywws/Plot.py", line 739, in DoPlot
    subprocess.check_call(['gnuplot', cmd_file])
  File "/usr/lib/python2.7/subprocess.py", line 535, in check_call
    retcode = call(*popenargs, **kwargs)
  File "/usr/lib/python2.7/subprocess.py", line 522, in call
    return Popen(*popenargs, **kwargs).wait()
  File "/usr/lib/python2.7/subprocess.py", line 710, in __init__
    errread, errwrite)
  File "/usr/lib/python2.7/subprocess.py", line 1335, in _execute_child
    raise child_exception
OSError: [Errno 2] No such file or directory
2017-01-22 21:50:56:pywws.ToService(underground_rf):rsp: success
2017-01-22 22:06:46:pywws.Logger:pywws version 16.12.0, build 1367 (e917ba9)
2017-01-22 22:06:53:pywws.Logger:pywws version 16.12.0, build 1367 (e917ba9)
2017-01-22 22:06:53:pywws.Logger:pywws version 16.12.0, build 1367 (e917ba9)
2017-01-22 22:07:19:root:Timeout waiting to acquire lock for /var/run/pywws.pid
Traceback (most recent call last):
  File "/usr/local/lib/python2.7/dist-packages/pywws/livelogdaemon.py", line 110, in main
    runner.do_action()
  File "/usr/local/lib/python2.7/dist-packages/daemon/runner.py", line 274, in do_action
    func(self)
  File "/usr/local/lib/python2.7/dist-packages/daemon/runner.py", line 182, in _start
    self.daemon_context.open()
  File "/usr/local/lib/python2.7/dist-packages/daemon/daemon.py", line 389, in open
    self.pidfile.__enter__()
  File "/usr/local/lib/python2.7/dist-packages/lockfile/__init__.py", line 197, in __enter__
    self.acquire()
  File "/usr/local/lib/python2.7/dist-packages/daemon/pidfile.py", line 60, in acquire
    super(TimeoutPIDLockFile, self).acquire(timeout, *args, **kwargs)
  File "/usr/local/lib/python2.7/dist-packages/lockfile/pidlockfile.py", line 85, in acquire
    self.path)
LockTimeout: Timeout waiting to acquire lock for /var/run/pywws.pid
2017-01-22 22:07:20:root:Timeout waiting to acquire lock for /var/run/pywws.pid
Traceback (most recent call last):
  File "/usr/local/lib/python2.7/dist-packages/pywws/livelogdaemon.py", line 110, in main
    runner.do_action()
  File "/usr/local/lib/python2.7/dist-packages/daemon/runner.py", line 274, in do_action
    func(self)
  File "/usr/local/lib/python2.7/dist-packages/daemon/runner.py", line 182, in _start
    self.daemon_context.open()
  File "/usr/local/lib/python2.7/dist-packages/daemon/daemon.py", line 389, in open
    self.pidfile.__enter__()
  File "/usr/local/lib/python2.7/dist-packages/lockfile/__init__.py", line 197, in __enter__
    self.acquire()
  File "/usr/local/lib/python2.7/dist-packages/daemon/pidfile.py", line 60, in acquire
    super(TimeoutPIDLockFile, self).acquire(timeout, *args, **kwargs)
  File "/usr/local/lib/python2.7/dist-packages/lockfile/pidlockfile.py", line 85, in acquire
    self.path)
LockTimeout: Timeout waiting to acquire lock for /var/run/pywws.pid
2017-01-22 22:07:43:pywws.LiveLog:[Errno 2] No such file or directory
Traceback (most recent call last):
  File "/usr/local/lib/python2.7/dist-packages/pywws/LiveLog.py", line 88, in LiveLog
    tasks.do_live(data)
  File "/usr/local/lib/python2.7/dist-packages/pywws/Tasks.py", line 301, in do_live
    self._do_cron(calib_data)
  File "/usr/local/lib/python2.7/dist-packages/pywws/Tasks.py", line 294, in _do_cron
    self._do_common(sections, live_data)
  File "/usr/local/lib/python2.7/dist-packages/pywws/Tasks.py", line 246, in _do_common
    upload = self.do_plot(template)
  File "/usr/local/lib/python2.7/dist-packages/pywws/Tasks.py", line 402, in do_plot
    self.plotter.DoPlot(input_xml, output_file) == 0):
  File "/usr/local/lib/python2.7/dist-packages/pywws/Plot.py", line 739, in DoPlot
    subprocess.check_call(['gnuplot', cmd_file])
  File "/usr/lib/python2.7/subprocess.py", line 535, in check_call
    retcode = call(*popenargs, **kwargs)
  File "/usr/lib/python2.7/subprocess.py", line 522, in call
    return Popen(*popenargs, **kwargs).wait()
  File "/usr/lib/python2.7/subprocess.py", line 710, in __init__
    errread, errwrite)
  File "/usr/lib/python2.7/subprocess.py", line 1335, in _execute_child
    raise child_exception
OSError: [Errno 2] No such file or directory
2017-01-22 22:07:45:pywws.ToService(underground_rf):exc: [Errno -2] Name or service not known
2017-01-22 22:10:07:pywws.Logger:pywws version 16.12.0, build 1367 (e917ba9)
2017-01-22 22:10:54:pywws.LiveLog:[Errno 2] No such file or directory
Traceback (most recent call last):
  File "/usr/local/lib/python2.7/dist-packages/pywws/LiveLog.py", line 88, in LiveLog
    tasks.do_live(data)
  File "/usr/local/lib/python2.7/dist-packages/pywws/Tasks.py", line 301, in do_live
    self._do_cron(calib_data)
  File "/usr/local/lib/python2.7/dist-packages/pywws/Tasks.py", line 294, in _do_cron
    self._do_common(sections, live_data)
  File "/usr/local/lib/python2.7/dist-packages/pywws/Tasks.py", line 246, in _do_common
    upload = self.do_plot(template)
  File "/usr/local/lib/python2.7/dist-packages/pywws/Tasks.py", line 402, in do_plot
    self.plotter.DoPlot(input_xml, output_file) == 0):
  File "/usr/local/lib/python2.7/dist-packages/pywws/Plot.py", line 739, in DoPlot
    subprocess.check_call(['gnuplot', cmd_file])
  File "/usr/lib/python2.7/subprocess.py", line 535, in check_call
    retcode = call(*popenargs, **kwargs)
  File "/usr/lib/python2.7/subprocess.py", line 522, in call
    return Popen(*popenargs, **kwargs).wait()
  File "/usr/lib/python2.7/subprocess.py", line 710, in __init__
    errread, errwrite)
  File "/usr/lib/python2.7/subprocess.py", line 1335, in _execute_child
    raise child_exception
OSError: [Errno 2] No such file or directory
2017-01-22 22:10:56:pywws.ToService(underground_rf):exc: [Errno -2] Name or service not known
2017-01-22 22:15:05:pywws.Logger:pywws version 16.12.0, build 1367 (e917ba9)
2017-01-22 22:15:42:pywws.LiveLog:[Errno 2] No such file or directory
Traceback (most recent call last):
  File "/usr/local/lib/python2.7/dist-packages/pywws/LiveLog.py", line 88, in LiveLog
    tasks.do_live(data)
  File "/usr/local/lib/python2.7/dist-packages/pywws/Tasks.py", line 301, in do_live
    self._do_cron(calib_data)
  File "/usr/local/lib/python2.7/dist-packages/pywws/Tasks.py", line 294, in _do_cron
    self._do_common(sections, live_data)
  File "/usr/local/lib/python2.7/dist-packages/pywws/Tasks.py", line 246, in _do_common
    upload = self.do_plot(template)
  File "/usr/local/lib/python2.7/dist-packages/pywws/Tasks.py", line 402, in do_plot
    self.plotter.DoPlot(input_xml, output_file) == 0):
  File "/usr/local/lib/python2.7/dist-packages/pywws/Plot.py", line 739, in DoPlot
    subprocess.check_call(['gnuplot', cmd_file])
  File "/usr/lib/python2.7/subprocess.py", line 535, in check_call
    retcode = call(*popenargs, **kwargs)
  File "/usr/lib/python2.7/subprocess.py", line 522, in call
    return Popen(*popenargs, **kwargs).wait()
  File "/usr/lib/python2.7/subprocess.py", line 710, in __init__
    errread, errwrite)
  File "/usr/lib/python2.7/subprocess.py", line 1335, in _execute_child
    raise child_exception
OSError: [Errno 2] No such file or directory
2017-01-22 22:15:44:pywws.ToService(underground_rf):exc: [Errno -2] Name or service not known
2017-01-22 22:20:06:pywws.Logger:pywws version 16.12.0, build 1367 (e917ba9)
2017-01-22 22:20:30:pywws.LiveLog:[Errno 2] No such file or directory
Traceback (most recent call last):
  File "/usr/local/lib/python2.7/dist-packages/pywws/LiveLog.py", line 88, in LiveLog
    tasks.do_live(data)
  File "/usr/local/lib/python2.7/dist-packages/pywws/Tasks.py", line 301, in do_live
    self._do_cron(calib_data)
  File "/usr/local/lib/python2.7/dist-packages/pywws/Tasks.py", line 294, in _do_cron
    self._do_common(sections, live_data)
  File "/usr/local/lib/python2.7/dist-packages/pywws/Tasks.py", line 246, in _do_common
    upload = self.do_plot(template)
  File "/usr/local/lib/python2.7/dist-packages/pywws/Tasks.py", line 402, in do_plot
    self.plotter.DoPlot(input_xml, output_file) == 0):
  File "/usr/local/lib/python2.7/dist-packages/pywws/Plot.py", line 739, in DoPlot
    subprocess.check_call(['gnuplot', cmd_file])
  File "/usr/lib/python2.7/subprocess.py", line 535, in check_call
    retcode = call(*popenargs, **kwargs)
  File "/usr/lib/python2.7/subprocess.py", line 522, in call
    return Popen(*popenargs, **kwargs).wait()
  File "/usr/lib/python2.7/subprocess.py", line 710, in __init__
    errread, errwrite)
  File "/usr/lib/python2.7/subprocess.py", line 1335, in _execute_child
    raise child_exception
OSError: [Errno 2] No such file or directory
2017-01-22 22:20:32:pywws.ToService(underground_rf):exc: [Errno -2] Name or service not known
2017-01-22 22:25:05:pywws.Logger:pywws version 16.12.0, build 1367 (e917ba9)
2017-01-22 22:26:06:pywws.LiveLog:[Errno 2] No such file or directory
Traceback (most recent call last):
  File "/usr/local/lib/python2.7/dist-packages/pywws/LiveLog.py", line 88, in LiveLog
    tasks.do_live(data)
  File "/usr/local/lib/python2.7/dist-packages/pywws/Tasks.py", line 301, in do_live
    self._do_cron(calib_data)
  File "/usr/local/lib/python2.7/dist-packages/pywws/Tasks.py", line 294, in _do_cron
    self._do_common(sections, live_data)
  File "/usr/local/lib/python2.7/dist-packages/pywws/Tasks.py", line 246, in _do_common
    upload = self.do_plot(template)
  File "/usr/local/lib/python2.7/dist-packages/pywws/Tasks.py", line 402, in do_plot
    self.plotter.DoPlot(input_xml, output_file) == 0):
  File "/usr/local/lib/python2.7/dist-packages/pywws/Plot.py", line 739, in DoPlot
    subprocess.check_call(['gnuplot', cmd_file])
  File "/usr/lib/python2.7/subprocess.py", line 535, in check_call
    retcode = call(*popenargs, **kwargs)
  File "/usr/lib/python2.7/subprocess.py", line 522, in call
    return Popen(*popenargs, **kwargs).wait()
  File "/usr/lib/python2.7/subprocess.py", line 710, in __init__
    errread, errwrite)
  File "/usr/lib/python2.7/subprocess.py", line 1335, in _execute_child
    raise child_exception
OSError: [Errno 2] No such file or directory
2017-01-22 22:26:08:pywws.ToService(underground_rf):exc: [Errno -2] Name or service not known
2017-01-22 22:30:06:pywws.Logger:pywws version 16.12.0, build 1367 (e917ba9)
2017-01-22 22:30:54:pywws.LiveLog:[Errno 2] No such file or directory
Traceback (most recent call last):
  File "/usr/local/lib/python2.7/dist-packages/pywws/LiveLog.py", line 88, in LiveLog
    tasks.do_live(data)
  File "/usr/local/lib/python2.7/dist-packages/pywws/Tasks.py", line 301, in do_live
    self._do_cron(calib_data)
  File "/usr/local/lib/python2.7/dist-packages/pywws/Tasks.py", line 294, in _do_cron
    self._do_common(sections, live_data)
  File "/usr/local/lib/python2.7/dist-packages/pywws/Tasks.py", line 246, in _do_common
    upload = self.do_plot(template)
  File "/usr/local/lib/python2.7/dist-packages/pywws/Tasks.py", line 402, in do_plot
    self.plotter.DoPlot(input_xml, output_file) == 0):
  File "/usr/local/lib/python2.7/dist-packages/pywws/Plot.py", line 739, in DoPlot
    subprocess.check_call(['gnuplot', cmd_file])
  File "/usr/lib/python2.7/subprocess.py", line 535, in check_call
    retcode = call(*popenargs, **kwargs)
  File "/usr/lib/python2.7/subprocess.py", line 522, in call
    return Popen(*popenargs, **kwargs).wait()
  File "/usr/lib/python2.7/subprocess.py", line 710, in __init__
    errread, errwrite)
  File "/usr/lib/python2.7/subprocess.py", line 1335, in _execute_child
    raise child_exception
OSError: [Errno 2] No such file or directory
2017-01-22 22:30:56:pywws.ToService(underground_rf):exc: [Errno -2] Name or service not known
